Workbook
Name cfgLongHireDays: Config!$B$38
Name cfgRecoveryTargetPct: Config!$B$39
Name cfgAlertAmberDays: Config!$B$37
Name cfgMassBalanceTolerancePct: Config!$B$40
Name lst_ApprovalStatus: '_Lists'!$A$5:$A$9
Name lst_AssetStatus: '_Lists'!$B$5:$B$11
Name lst_AuditType: '_Lists'!$C$5:$C$10
Name lst_Compliance: '_Lists'!$D$5:$D$9
Name lst_ContainerType: '_Lists'!$E$5:$E$15
Name lst_CustomerType: '_Lists'!$F$5:$F$10
Name lst_Direction: '_Lists'!$G$5:$G$6
Name lst_DocStatus: '_Lists'!$H$5:$H$9
Name lst_DocType: '_Lists'!$I$5:$I$13
Name lst_EmailCategory: '_Lists'!$J$5:$J$15
Name lst_IncidentType: '_Lists'!$K$5:$K$13
Name lst_InvoiceStatus: '_Lists'!$L$5:$L$11
Name lst_JobStatus: '_Lists'!$M$5:$M$14
Name lst_LikertScore: '_Lists'!$N$5:$N$9
Name lst_MovementType: '_Lists'!$O$5:$O$11
Name lst_NCRSource: '_Lists'!$P$5:$P$13
Name lst_NCRType: '_Lists'!$Q$5:$Q$9
Name lst_OpenClosed: '_Lists'!$R$5:$R$9
Name lst_OutletType: '_Lists'!$S$5:$S$13
Name lst_PaymentTerms: '_Lists'!$T$5:$T$11
Name lst_PermitType: '_Lists'!$U$5:$U$12
Name lst_RecordStatus: '_Lists'!$V$5:$V$7
Name lst_RecoveryRoute: '_Lists'!$W$5:$W$9
Name lst_RiskType: '_Lists'!$X$5:$X$6
Name lst_ServiceType: '_Lists'!$Y$5:$Y$11
Name lst_Severity: '_Lists'!$Z$5:$Z$7
Name lst_Standard: '_Lists'!$AA$5:$AA$10
Name lst_StreamGroup: '_Lists'!$AB$5:$AB$17
Name lst_UOM: '_Lists'!$AC$5:$AC$11
Name lst_WTNDocType: '_Lists'!$AD$5:$AD$7
Name lst_YesNo: '_Lists'!$AE$5:$AE$6

Sheet Start
B2: Acorn Recyclers - Operations Console
B3: The front end. It holds no data of its own - it reads the three workbooks in 01_Data, so it can be closed, copied or rebuilt without ever putting a record at risk.
B6: Every day
B7: 1. Sync | C7: Pulls the three data workbooks into this file. Everything else reads the result. Takes a couple of seconds; do it whenever you sit down.
B8: 2. Today | C8: The job board: what is booked, allocated, on site and awaiting collection.
B9: 3. Import Weighbridge | C9: Reads every CSV in 02_Inbox\Weighbridge, maps the columns using the WB_Map sheet, and writes tickets into the Operations workbook.
B10: 4. Scrape Outlook | C10: Reads the Outlook intake folder, classifies each mail against the Rules sheet, saves the attachments and logs it. Safe to run repeatedly - nothing is ever logged twice.
B11: 5. Intake | C11: Work through what Outlook brought in and turn bookings into jobs.
B13: When you need it
B14: Generate Document | C14: Builds a transfer note, confirmation, quote or NCR from a Word template and files it against the job.
B15: Reconcile Tickets | C15: Matches unmatched weighbridge tickets to jobs on vehicle and date.
B16: Build Invoice Lines | C16: Turns completed jobs and weighed tonnage into charge lines ready to export to the accounts package.
B18: Weekly / monthly
B19: Alerts | C19: Every renewal, calibration, licence, training record and overdue action in one list. If this sheet is empty you are in good shape.
B20: Dashboard | C20: Live position, month to date, and a rolling twelve months of tonnage and recovery.
B21: Document Control Check | C21: Reconciles 04_Documents\Controlled against the document register - finds uncontrolled files and documents overdue review.
B22: Archive Year | C22: Moves a closed year into 06_Archive. It will not touch anything still inside its statutory retention window.
B24: Before you start
C25: Set RootPath on the Config sheet to wherever the AcornOps folder actually lives.
C26: Put your initials in CurrentUser on the Config sheet - it stamps everything you create.
C27: Fill in the company block on Config. Those values are printed onto every transfer note.
C28: Check WB_Map against a real export from the weighbridge software before the first import.
C29: Delete the amber example row from each sheet of the three data workbooks (Admin > Clear Example Rows).
B31: If the buttons are missing | C31: This file is .xlsx until the installer imports the macros and saves it as AcornOps_Console.xlsm. Run 99_Scripts\Install-AcornOps.ps1, then open the .xlsm.

Sheet Dashboard
B1: Operations Dashboard
B2: Live formulas over the Data_* caches. Press Sync first - every figure here is only as current as the last sync.
B4: Reporting month | C4: =EOMONTH(TODAY(),-1)+1 | E4: Month end | F4: =EOMONTH($C$4,0) | H4: Data last synced | I4: never
B6: Live position | E6: Reporting month | H6: Compliance
B7: Jobs scheduled today | C7: =COUNTIFS(Data_Jobs!$I$2:$I$20000,TODAY()) | E7: Tonnes received (In) | F7: =SUMIFS(Data_WeighTickets!$W$2:$W$20000,Data_WeighTickets!$V$2:$V$20000,$C$4,Data_WeighTickets!$C$2:$C$20000,"In") | H7: Permits / licences expired | I7: =COUNTIFS(Data_Permits!$G$2:$G$20000,">0",Data_Permits!$G$2:$G$20000,"<"&TODAY())
B8: Jobs completed today | C8: =COUNTIFS(Data_Jobs!$J$2:$J$20000,TODAY()) | E8: Tonnes despatched (Out) | F8: =SUMIFS(Data_WeighTickets!$W$2:$W$20000,Data_WeighTickets!$V$2:$V$20000,$C$4,Data_WeighTickets!$C$2:$C$20000,"Out") | H8: Permits / licences due soon | I8: =COUNTIFS(Data_Permits!$G$2:$G$20000,">="&TODAY(),Data_Permits!$G$2:$G$20000,"<="&TODAY()+cfgAlertAmberDays)
B9: Open jobs | C9: =COUNTIFS(Data_Jobs!$W$2:$W$20000,1) | E9: Tonnes diverted from landfill | F9: =F8-F10 | H9: Vehicle renewals overdue | I9: =COUNTIFS(Data_Vehicles!$G$2:$G$20000,">0",Data_Vehicles!$G$2:$G$20000,"<"&TODAY())+COUNTIFS(Data_Vehicles!$H$2:$H$20000,">0",Data_Vehicles!$H$2:$H$20000,"<"&TODAY())+COUNTIFS(Data_Vehicles!$I$2:$I$20000,">0",Data_Vehicles!$I$2:$I$20000,"<"&TODAY())+COUNTIFS(Data_Vehicles!$J$2:$J$20000,">0",Data_Vehicles!$J$2:$J$20000,"<"&TODAY())+COUNTIFS(Data_Vehicles!$K$2:$K$20000,">0",Data_Vehicles!$K$2:$K$20000,"<"&TODAY())
B10: Containers on hire | C10: =COUNTIFS(Data_Assets!$F$2:$F$20000,"On Hire") | E10: Tonnes to landfill | F10: =SUMIFS(Data_WeighTickets!$W$2:$W$20000,Data_WeighTickets!$V$2:$V$20000,$C$4,Data_WeighTickets!$C$2:$C$20000,"Out",Data_WeighTickets!$T$2:$T$20000,"Landfill") | H10: Driver renewals overdue | I10: =COUNTIFS(Data_Drivers!$F$2:$F$20000,">0",Data_Drivers!$F$2:$F$20000,"<"&TODAY())+COUNTIFS(Data_Drivers!$G$2:$G$20000,">0",Data_Drivers!$G$2:$G$20000,"<"&TODAY())+COUNTIFS(Data_Drivers!$I$2:$I$20000,">0",Data_Drivers!$I$2:$I$20000,"<"&TODAY())
B11: Containers available | C11: =COUNTIFS(Data_Assets!$F$2:$F$20000,"Available") | E11: Recovery rate | F11: =IF($F$8=0,"",$F$9/$F$8) | H11: Calibration overdue | I11: =COUNTIFS(Data_Calibration!$H$2:$H$20000,">0",Data_Calibration!$H$2:$H$20000,"<"&TODAY())
B12: Containers off the road | C12: =COUNTIFS(Data_Assets!$F$2:$F$20000,"Maintenance")+COUNTIFS(Data_Assets!$F$2:$F$20000,"Repair") | E12: Mass balance variance | F12: =IF($F$7=0,"",($F$7-$F$8)/$F$7) | H12: Training expired | I12: =COUNTIFS(Data_Training!$H$2:$H$20000,">0",Data_Training!$H$2:$H$20000,"<"&TODAY())
B13: Hires over threshold | C13: =COUNTIFS(Data_Assets!$F$2:$F$20000,"On Hire",Data_Assets!$N$2:$N$20000,">="&cfgLongHireDays) | E13: Jobs completed | F13: =COUNTIFS(Data_Jobs!$V$2:$V$20000,$C$4,Data_Jobs!$J$2:$J$20000,">0") | H13: Documents overdue review | I13: =COUNTIFS(Data_DocRegister!$J$2:$J$20000,">0",Data_DocRegister!$J$2:$J$20000,"<"&TODAY())
B14: Unmatched weigh tickets | C14: =COUNTIFS(Data_WeighTickets!$Q$2:$Q$20000,"No") | E14: Transfer notes raised | F14: =COUNTIFS(Data_TransferNotes!$S$2:$S$20000,$C$4) | H14: NCRs open | I14: =COUNTIFS(Data_NCR!$Q$2:$Q$20000,"Open")+COUNTIFS(Data_NCR!$Q$2:$Q$20000,"In Progress")+COUNTIFS(Data_NCR!$Q$2:$Q$20000,"Awaiting Verification")
B15: Draft invoice lines | C15: =COUNTIFS(Data_InvoiceLines!$N$2:$N$20000,"Draft") | E15: Invoiced (net) | F15: =SUMIFS(Data_InvoiceLines!$J$2:$J$20000,Data_InvoiceLines!$P$2:$P$20000,$C$4) | H15: NCR actions overdue | I15: =COUNTIFS(Data_NCR!$S$2:$S$20000,"YES")
B16: Draft value | C16: =SUMIFS(Data_InvoiceLines!$J$2:$J$20000,Data_InvoiceLines!$N$2:$N$20000,"Draft") | E16: Average £ per tonne received | F16: =IF($F$7=0,"",$F$15/$F$7) | H16: Incidents open | I16: =COUNTIFS(Data_Incidents!$P$2:$P$20000,"Open")+COUNTIFS(Data_Incidents!$P$2:$P$20000,"In Progress")
H17: Audits overdue | I17: =COUNTIFS(Data_Audits!$E$2:$E$20000,"<"&TODAY(),Data_Audits!$E$2:$E$20000,">0",Data_Audits!$F$2:$F$20000,"")
B19: Rolling twelve months
B20: Month | C20: Tonnes in | D20: Tonnes out | E20: Diverted | F20: Landfill | G20: Recovery % | H20: Jobs done | I20: Invoiced net
B21: =DATE(YEAR($C$4),MONTH($C$4)-11,1) | C21: =SUMIFS(Data_WeighTickets!$W$2:$W$20000,Data_WeighTickets!$V$2:$V$20000,$B21,Data_WeighTickets!$C$2:$C$20000,"In") | D21: =SUMIFS(Data_WeighTickets!$W$2:$W$20000,Data_WeighTickets!$V$2:$V$20000,$B21,Data_WeighTickets!$C$2:$C$20000,"Out") | E21: =$D21-$F21 | F21: =SUMIFS(Data_WeighTickets!$W$2:$W$20000,Data_WeighTickets!$V$2:$V$20000,$B21,Data_WeighTickets!$C$2:$C$20000,"Out",Data_WeighTickets!$T$2:$T$20000,"Landfill") | G21: =IF($D21=0,"",$E21/$D21) | H21: =COUNTIFS(Data_Jobs!$V$2:$V$20000,$B21,Data_Jobs!$J$2:$J$20000,">0") | I21: =SUMIFS(Data_InvoiceLines!$J$2:$J$20000,Data_InvoiceLines!$P$2:$P$20000,$B21)
B22: =EDATE($B21,1) | C22: =SUMIFS(Data_WeighTickets!$W$2:$W$20000,Data_WeighTickets!$V$2:$V$20000,$B22,Data_WeighTickets!$C$2:$C$20000,"In") | D22: =SUMIFS(Data_WeighTickets!$W$2:$W$20000,Data_WeighTickets!$V$2:$V$20000,$B22,Data_WeighTickets!$C$2:$C$20000,"Out") | E22: =$D22-$F22 | F22: =SUMIFS(Data_WeighTickets!$W$2:$W$20000,Data_WeighTickets!$V$2:$V$20000,$B22,Data_WeighTickets!$C$2:$C$20000,"Out",Data_WeighTickets!$T$2:$T$20000,"Landfill") | G22: =IF($D22=0,"",$E22/$D22) | H22: =COUNTIFS(Data_Jobs!$V$2:$V$20000,$B22,Data_Jobs!$J$2:$J$20000,">0") | I22: =SUMIFS(Data_InvoiceLines!$J$2:$J$20000,Data_InvoiceLines!$P$2:$P$20000,$B22)
B23: =EDATE($B22,1) | C23: =SUMIFS(Data_WeighTickets!$W$2:$W$20000,Data_WeighTickets!$V$2:$V$20000,$B23,Data_WeighTickets!$C$2:$C$20000,"In") | D23: =SUMIFS(Data_WeighTickets!$W$2:$W$20000,Data_WeighTickets!$V$2:$V$20000,$B23,Data_WeighTickets!$C$2:$C$20000,"Out") | E23: =$D23-$F23 | F23: =SUMIFS(Data_WeighTickets!$W$2:$W$20000,Data_WeighTickets!$V$2:$V$20000,$B23,Data_WeighTickets!$C$2:$C$20000,"Out",Data_WeighTickets!$T$2:$T$20000,"Landfill") | G23: =IF($D23=0,"",$E23/$D23) | H23: =COUNTIFS(Data_Jobs!$V$2:$V$20000,$B23,Data_Jobs!$J$2:$J$20000,">0") | I23: =SUMIFS(Data_InvoiceLines!$J$2:$J$20000,Data_InvoiceLines!$P$2:$P$20000,$B23)
B24: =EDATE($B23,1) | C24: =SUMIFS(Data_WeighTickets!$W$2:$W$20000,Data_WeighTickets!$V$2:$V$20000,$B24,Data_WeighTickets!$C$2:$C$20000,"In") | D24: =SUMIFS(Data_WeighTickets!$W$2:$W$20000,Data_WeighTickets!$V$2:$V$20000,$B24,Data_WeighTickets!$C$2:$C$20000,"Out") | E24: =$D24-$F24 | F24: =SUMIFS(Data_WeighTickets!$W$2:$W$20000,Data_WeighTickets!$V$2:$V$20000,$B24,Data_WeighTickets!$C$2:$C$20000,"Out",Data_WeighTickets!$T$2:$T$20000,"Landfill") | G24: =IF($D24=0,"",$E24/$D24) | H24: =COUNTIFS(Data_Jobs!$V$2:$V$20000,$B24,Data_Jobs!$J$2:$J$20000,">0") | I24: =SUMIFS(Data_InvoiceLines!$J$2:$J$20000,Data_InvoiceLines!$P$2:$P$20000,$B24)
B25: =EDATE($B24,1) | C25: =SUMIFS(Data_WeighTickets!$W$2:$W$20000,Data_WeighTickets!$V$2:$V$20000,$B25,Data_WeighTickets!$C$2:$C$20000,"In") | D25: =SUMIFS(Data_WeighTickets!$W$2:$W$20000,Data_WeighTickets!$V$2:$V$20000,$B25,Data_WeighTickets!$C$2:$C$20000,"Out") | E25: =$D25-$F25 | F25: =SUMIFS(Data_WeighTickets!$W$2:$W$20000,Data_WeighTickets!$V$2:$V$20000,$B25,Data_WeighTickets!$C$2:$C$20000,"Out",Data_WeighTickets!$T$2:$T$20000,"Landfill") | G25: =IF($D25=0,"",$E25/$D25) | H25: =COUNTIFS(Data_Jobs!$V$2:$V$20000,$B25,Data_Jobs!$J$2:$J$20000,">0") | I25: =SUMIFS(Data_InvoiceLines!$J$2:$J$20000,Data_InvoiceLines!$P$2:$P$20000,$B25)
B26: =EDATE($B25,1) | C26: =SUMIFS(Data_WeighTickets!$W$2:$W$20000,Data_WeighTickets!$V$2:$V$20000,$B26,Data_WeighTickets!$C$2:$C$20000,"In") | D26: =SUMIFS(Data_WeighTickets!$W$2:$W$20000,Data_WeighTickets!$V$2:$V$20000,$B26,Data_WeighTickets!$C$2:$C$20000,"Out") | E26: =$D26-$F26 | F26: =SUMIFS(Data_WeighTickets!$W$2:$W$20000,Data_WeighTickets!$V$2:$V$20000,$B26,Data_WeighTickets!$C$2:$C$20000,"Out",Data_WeighTickets!$T$2:$T$20000,"Landfill") | G26: =IF($D26=0,"",$E26/$D26) | H26: =COUNTIFS(Data_Jobs!$V$2:$V$20000,$B26,Data_Jobs!$J$2:$J$20000,">0") | I26: =SUMIFS(Data_InvoiceLines!$J$2:$J$20000,Data_InvoiceLines!$P$2:$P$20000,$B26)
B27: =EDATE($B26,1) | C27: =SUMIFS(Data_WeighTickets!$W$2:$W$20000,Data_WeighTickets!$V$2:$V$20000,$B27,Data_WeighTickets!$C$2:$C$20000,"In") | D27: =SUMIFS(Data_WeighTickets!$W$2:$W$20000,Data_WeighTickets!$V$2:$V$20000,$B27,Data_WeighTickets!$C$2:$C$20000,"Out") | E27: =$D27-$F27 | F27: =SUMIFS(Data_WeighTickets!$W$2:$W$20000,Data_WeighTickets!$V$2:$V$20000,$B27,Data_WeighTickets!$C$2:$C$20000,"Out",Data_WeighTickets!$T$2:$T$20000,"Landfill") | G27: =IF($D27=0,"",$E27/$D27) | H27: =COUNTIFS(Data_Jobs!$V$2:$V$20000,$B27,Data_Jobs!$J$2:$J$20000,">0") | I27: =SUMIFS(Data_InvoiceLines!$J$2:$J$20000,Data_InvoiceLines!$P$2:$P$20000,$B27)
B28: =EDATE($B27,1) | C28: =SUMIFS(Data_WeighTickets!$W$2:$W$20000,Data_WeighTickets!$V$2:$V$20000,$B28,Data_WeighTickets!$C$2:$C$20000,"In") | D28: =SUMIFS(Data_WeighTickets!$W$2:$W$20000,Data_WeighTickets!$V$2:$V$20000,$B28,Data_WeighTickets!$C$2:$C$20000,"Out") | E28: =$D28-$F28 | F28: =SUMIFS(Data_WeighTickets!$W$2:$W$20000,Data_WeighTickets!$V$2:$V$20000,$B28,Data_WeighTickets!$C$2:$C$20000,"Out",Data_WeighTickets!$T$2:$T$20000,"Landfill") | G28: =IF($D28=0,"",$E28/$D28) | H28: =COUNTIFS(Data_Jobs!$V$2:$V$20000,$B28,Data_Jobs!$J$2:$J$20000,">0") | I28: =SUMIFS(Data_InvoiceLines!$J$2:$J$20000,Data_InvoiceLines!$P$2:$P$20000,$B28)
B29: =EDATE($B28,1) | C29: =SUMIFS(Data_WeighTickets!$W$2:$W$20000,Data_WeighTickets!$V$2:$V$20000,$B29,Data_WeighTickets!$C$2:$C$20000,"In") | D29: =SUMIFS(Data_WeighTickets!$W$2:$W$20000,Data_WeighTickets!$V$2:$V$20000,$B29,Data_WeighTickets!$C$2:$C$20000,"Out") | E29: =$D29-$F29 | F29: =SUMIFS(Data_WeighTickets!$W$2:$W$20000,Data_WeighTickets!$V$2:$V$20000,$B29,Data_WeighTickets!$C$2:$C$20000,"Out",Data_WeighTickets!$T$2:$T$20000,"Landfill") | G29: =IF($D29=0,"",$E29/$D29) | H29: =COUNTIFS(Data_Jobs!$V$2:$V$20000,$B29,Data_Jobs!$J$2:$J$20000,">0") | I29: =SUMIFS(Data_InvoiceLines!$J$2:$J$20000,Data_InvoiceLines!$P$2:$P$20000,$B29)
B30: =EDATE($B29,1) | C30: =SUMIFS(Data_WeighTickets!$W$2:$W$20000,Data_WeighTickets!$V$2:$V$20000,$B30,Data_WeighTickets!$C$2:$C$20000,"In") | D30: =SUMIFS(Data_WeighTickets!$W$2:$W$20000,Data_WeighTickets!$V$2:$V$20000,$B30,Data_WeighTickets!$C$2:$C$20000,"Out") | E30: =$D30-$F30 | F30: =SUMIFS(Data_WeighTickets!$W$2:$W$20000,Data_WeighTickets!$V$2:$V$20000,$B30,Data_WeighTickets!$C$2:$C$20000,"Out",Data_WeighTickets!$T$2:$T$20000,"Landfill") | G30: =IF($D30=0,"",$E30/$D30) | H30: =COUNTIFS(Data_Jobs!$V$2:$V$20000,$B30,Data_Jobs!$J$2:$J$20000,">0") | I30: =SUMIFS(Data_InvoiceLines!$J$2:$J$20000,Data_InvoiceLines!$P$2:$P$20000,$B30)
B31: =EDATE($B30,1) | C31: =SUMIFS(Data_WeighTickets!$W$2:$W$20000,Data_WeighTickets!$V$2:$V$20000,$B31,Data_WeighTickets!$C$2:$C$20000,"In") | D31: =SUMIFS(Data_WeighTickets!$W$2:$W$20000,Data_WeighTickets!$V$2:$V$20000,$B31,Data_WeighTickets!$C$2:$C$20000,"Out") | E31: =$D31-$F31 | F31: =SUMIFS(Data_WeighTickets!$W$2:$W$20000,Data_WeighTickets!$V$2:$V$20000,$B31,Data_WeighTickets!$C$2:$C$20000,"Out",Data_WeighTickets!$T$2:$T$20000,"Landfill") | G31: =IF($D31=0,"",$E31/$D31) | H31: =COUNTIFS(Data_Jobs!$V$2:$V$20000,$B31,Data_Jobs!$J$2:$J$20000,">0") | I31: =SUMIFS(Data_InvoiceLines!$J$2:$J$20000,Data_InvoiceLines!$P$2:$P$20000,$B31)
B32: =EDATE($B31,1) | C32: =SUMIFS(Data_WeighTickets!$W$2:$W$20000,Data_WeighTickets!$V$2:$V$20000,$B32,Data_WeighTickets!$C$2:$C$20000,"In") | D32: =SUMIFS(Data_WeighTickets!$W$2:$W$20000,Data_WeighTickets!$V$2:$V$20000,$B32,Data_WeighTickets!$C$2:$C$20000,"Out") | E32: =$D32-$F32 | F32: =SUMIFS(Data_WeighTickets!$W$2:$W$20000,Data_WeighTickets!$V$2:$V$20000,$B32,Data_WeighTickets!$C$2:$C$20000,"Out",Data_WeighTickets!$T$2:$T$20000,"Landfill") | G32: =IF($D32=0,"",$E32/$D32) | H32: =COUNTIFS(Data_Jobs!$V$2:$V$20000,$B32,Data_Jobs!$J$2:$J$20000,">0") | I32: =SUMIFS(Data_InvoiceLines!$J$2:$J$20000,Data_InvoiceLines!$P$2:$P$20000,$B32)
B33: Twelve month total | C33: =SUM(C21:C32) | D33: =SUM(D21:D32) | E33: =SUM(E21:E32) | F33: =SUM(F21:F32) | G33: =IF($D33=0,"",$E33/$D33) | H33: =SUM(H21:H32) | I33: =SUM(I21:I32)
B35: How the recovery rate is worked out
B36: Every weighbridge ticket carries an EWC code. The EWC code carries a RecoveryRoute on the WasteStreams sheet of the Master workbook - Recycling, Reuse, Recovery (Energy), Treatment or Landfill.
B37: Diverted tonnage is everything despatched on an Out ticket whose route is not Landfill. The rate is diverted divided by total despatched.
B38: So the number is only ever as honest as the RecoveryRoute column. Review it whenever you change outlet, and keep the outlet permit checks in tblOutlets up to date - that is the evidence behind the figure.

Sheet Today
A1: Today's job board
A2: Rebuilt by the Today button. Sorted by scheduled date then customer. Editing this sheet changes nothing - make the change in the Operations workbook, or through Job Entry, then re-run.
A4: JobID | B4: Scheduled | C4: Service | D4: Customer | E4: Site | F4: Postcode | G4: Container | H4: Asset | I4: Driver | J4: Vehicle | K4: Status | L4: Days on hire | M4: Permit | N4: Notes

Sheet Alerts
A1: Compliance alerts
A2: Rebuilt by the Alerts button from every dated field across the three workbooks. Red is already past, amber falls due inside Config > AlertAmberDays. An empty sheet means nothing is due.
A4: Severity | B4: Days | C4: Due | D4: Area | E4: Record | F4: Reference | G4: What is due | H4: Owner | I4: Where to fix it

Sheet Intake
A1: Outlook intake review
A2: Rebuilt by the Scrape Outlook button. Work down the list: set an outcome, then use Convert to Job on the rows that are bookings. Nothing here is written back until you act on it.
A4: EmailID | B4: Received | C4: From | D4: Sender email | E4: Subject | F4: Category | G4: Suggested action | H4: Customer | I4: Job | J4: Postcode | K4: Container | L4: Wanted for | M4: Attachments | N4: Outcome

Sheet WB_Staging
A1: Weighbridge import staging
A2: Where the raw CSV rows land before they are written to the Operations workbook. Rows flagged as a problem are left here so you can fix the mapping on WB_Map and re-run; nothing part-imported is ever written through.
A4: SourceFile | B4: Row | C4: TicketNo | D4: TicketDateTime | E4: Direction | F4: VehicleReg | G4: JobID | H4: CustomerID | I4: OutletID | J4: EWCCode | K4: GrossKg | L4: TareKg | M4: NetKg | N4: Weighbridge | O4: Operator | P4: Notes | Q4: Status | R4: Message

Sheet Config
A1: Configuration
A2: Everything the macros need to know about this installation. Change the Value column only. Blue values are yours to set.
A4: Setting | B4: Value | C4: Notes
A5: --- Paths ---
A6: RootPath | B6: C:\AcornOps | C6: The one setting you must get right. Everything else hangs off it. On a shared drive use the UNC path (\\SERVER\Acorn\AcornOps), not a mapped letter - drive letters differ between PCs.
A7: MasterWorkbook | B7: 01_Data\AcornOps_Master.xlsx | C7: Relative to RootPath.
A8: OperationsWorkbook | B8: 01_Data\AcornOps_Operations.xlsx | C8: Relative to RootPath.
A9: ComplianceWorkbook | B9: 01_Data\AcornOps_Compliance.xlsx | C9: Relative to RootPath.
A10: TemplatesFolder | B10: 04_Documents\Templates | C10: Word templates with {{Token}} placeholders.
A11: JobDocsFolder | B11: 04_Documents\Jobs | C11: One subfolder per job, created on demand.
A12: ControlledDocsFolder | B12: 04_Documents\Controlled | C12: Scanned by the document control check.
A13: WeighbridgeInbox | B13: 02_Inbox\Weighbridge | C13: Drop the weighbridge CSV exports here.
A14: EmailInbox | B14: 02_Inbox\Email | C14: Outlook attachments land here, foldered by EmailID.
A15: ArchiveFolder | B15: 06_Archive | C15: Where the archive routine moves closed years.
A16: LogFolder | B16: 00_Admin\Logs | C16: One log file per day. Every automated action is recorded.
A17: --- Outlook intake ---
A18: OutlookAccount | C18: Blank = the default mailbox. For a shared mailbox put its display name exactly as it appears in the Outlook folder pane.
A19: OutlookIntakeFolder | B19: Inbox\Acorn Intake | C19: Backslash-separated path below the mailbox root. Set an Outlook rule to drop enquiries here.
A20: OutlookProcessedFolder | B20: Inbox\Acorn Intake\Logged | C20: Logged mail is moved here. Leave blank to leave mail where it is.
A21: OutlookLookbackDays | B21: 14 | C21: Ignore anything older. Keeps the scrape quick.
A22: OutlookMarkCategory | B22: Acorn: Logged | C22: Category stamped on a message once it is logged.
A23: OutlookSaveAttachments | B23: Yes | C23: Yes = save attachments into EmailInbox\<EmailID>\.
A24: OutlookMaxBodyChars | B24: 1000 | C24: How much body text to keep in the log, for searching.
A25: --- Company details (used on generated documents) ---
A26: CompanyName | B26: Acorn Recyclers Ltd
A27: CompanyAddress | C27: Single line - it is written straight onto documents.
A28: CompanyPostcode
A29: CompanyPhone
A30: CompanyEmail
A31: CompanyVATNumber
A32: CarrierLicence | C32: Waste carrier registration. Legally required on every transfer note.
A33: EnvironmentalPermit | C33: Permit number for the transfer station.
A34: CompanySICCode | B34: 38320 | C34: Recovery of sorted materials. Change if yours differs.
A35: --- Rules & thresholds ---
A36: VATRate | B36: 0.2 | C36: Applied to new invoice lines. Stored as a fraction.
A37: AlertAmberDays | B37: 30 | C37: How far ahead a renewal turns amber on the Alerts sheet.
A38: LongHireDays | B38: 14 | C38: A container out longer than this is flagged for chasing.
A39: RecoveryTargetPct | B39: 0.9 | C39: Green/amber/red banding on the recovery rate.
A40: MassBalanceTolerancePct | B40: 0.05 | C40: In-vs-out variance above this is flagged. Some variance is normal (moisture, stock on site); a large one usually means missing Out tickets.
A41: AutoCreateJobFromEmail | B41: No | C41: Yes lets the intake routine raise a Booked job straight from a matched email. Leave No until you trust the classification rules.
...

Sheet Rules
A1: Outlook classification rules
A2: Applied in Priority order, lowest number first; the first rule that matches wins. The catch-all on priority 900 has an empty keyword so it always matches - keep it last so nothing ever falls through unclassified without you seeing it.
A4: Priority | B4: Field | C4: MatchType | D4: Keyword | E4: Category | F4: Action | G4: Enabled
A5: 10 | B5: Subject | C5: Contains | D5: weighbridge | E5: Weighbridge Ticket | F5: Save attachment to weighbridge inbox | G5: Yes
A6: 20 | B6: Subject | C6: Contains | D6: ticket | E6: Weighbridge Ticket | F6: Save attachment to weighbridge inbox | G6: Yes
A7: 30 | B7: Subject | C7: Contains | D7: skip | E7: Booking | F7: Flag for booking | G7: Yes
A8: 40 | B8: Subject | C8: Contains | D8: collection | E8: Booking | F8: Flag for booking | G8: Yes
A9: 50 | B9: Subject | C9: Contains | D9: exchange | E9: Booking | F9: Flag for booking | G9: Yes
A10: 60 | B10: Subject | C10: Contains | D10: quote | E10: Quote Request | F10: Flag for quoting | G10: Yes
A11: 70 | B11: Subject | C11: Contains | D11: price | E11: Quote Request | F11: Flag for quoting | G11: Yes
A12: 80 | B12: Subject | C12: Contains | D12: invoice | E12: Invoice Query | F12: Route to accounts | G12: Yes
A13: 90 | B13: Subject | C13: Contains | D13: credit | E13: Invoice Query | F13: Route to accounts | G13: Yes
A14: 100 | B14: Subject | C14: Contains | D14: complaint | E14: Complaint | F14: Raise NCR | G14: Yes
A15: 110 | B15: Body | C15: Contains | D15: not happy | E15: Complaint | F15: Raise NCR | G15: Yes
A16: 120 | B16: From | C16: Contains | D16: @environment-agency.gov.uk | E16: Compliance | F16: Route to compliance | G16: Yes
... A19: 150 | B19: Subject | C19: Contains | D19: duty of care | E19: Compliance | F19: Route to compliance | G19: Yes
A20: 900 | B20: Any | C20: Contains | E20: Unclassified | F20: Review manually | G20: Yes

Sheet WB_Map
A1: Weighbridge import column map
A2: This is the adapter between whatever the skip software exports and the fields this platform needs. Open a real export, copy its column headings into SourceHeader, and the importer will cope with the rest. Nothing here requires a code change - if the software is updated and the headings move, you fix it on this sheet.
A4: TargetField | B4: SourceHeader | C4: SourceHeader2 | D4: Transform | E4: Notes
A5: TicketNo | B5: Ticket No | D5: Trim | E5: Must be unique. Re-importing the same number updates the row.
A6: TicketDateTime | B6: Date/Time | D6: DateTime | E6: If the export splits date and time, put the date header here and the time header in SourceHeader2.
A7: Direction | B7: In/Out | D7: Map:IN=In;OUT=Out;I=In;O=Out | E7: Map: pairs rewrite the source value.
A8: VehicleReg | B8: Vehicle | D8: UpperNoSpace | E8: YJ71KLM and YJ71 KLM must not become two vehicles.
A9: JobID | B9: Order Ref | D9: Trim | E9: Leave the SourceHeader blank if the export has no job reference; the reconcile step will match on vehicle and date instead.
A10: CustomerID | B10: Account | D10: Trim
A11: OutletID | B11: Destination | D11: Trim
A12: EWCCode | B12: EWC | D12: DigitsOnly | E12: Strips spaces and the * hazardous marker.
A13: GrossKg | B13: Gross | D13: Number | E13: Use TonnesToKg if the bridge exports tonnes.
A14: TareKg | B14: Tare | D14: Number
A15: Weighbridge | B15: Bridge | D15: Trim
A16: Operator | B16: Operator | D16: Trim
A17: Notes | B17: Comments | D17: Trim

Sheet DocGen
A1: Document templates
A2: Word templates live in 04_Documents\Templates and use {{Token}} placeholders. The token list is on the TokenRef sheet. Add a template by dropping the .docx in the folder and adding a row here - no macro changes needed.
A4: TemplateFile | B4: DocType | C4: Source | D4: OutputName | E4: SaveAs | F4: Description
A5: WasteTransferNote.docx | B5: Waste Transfer Note | C5: TransferNote | D5: {{WTNRef}} Waste Transfer Note | E5: Both | F5: Section A-D duty of care note. Raised per job or per season ticket.
A6: HazardousConsignmentNote.docx | B6: Hazardous Consignment Note | C6: TransferNote | D6: {{WTNRef}} Consignment Note | E6: Both | F6: Used automatically when the EWC code is flagged Hazardous.
A7: JobConfirmation.docx | B7: Job Confirmation | C7: Job | D7: {{JobID}} Confirmation | E7: Both | F7: Sent back to the customer when a booking is accepted.
A8: Quotation.docx | B8: Quotation | C8: Job | D8: {{JobID}} Quotation | E8: Both | F8: Priced from tblPriceList.
A9: DutyOfCareStatement.docx | B9: Duty of Care Statement | C9: Customer | D9: {{CustomerID}} Duty of Care | E9: Both | F9: Annual statement of where a customer's waste went and the recovery achieved.
A10: NCRReport.docx | B10: Nonconformity Report | C10: NCR | D10: {{NCRID}} NCR | E10: Both | F10: Full NCR record for the audit file.
A11: ToolboxTalkRecord.docx | B11: Toolbox Talk Record | C11: Manual | D11: Toolbox Talk {{Date}} | E11: Both | F11: Attendance record; files into 05_Compliance\Training.
A12: SiteInductionRecord.docx | B12: Site Induction Record | C12: Manual | D12: Induction {{Name}} | E12: Both | F12: Visitor and new-starter induction.

Sheet TokenRef
A1: Word merge tokens
A2: Type these into a Word template exactly as shown, braces included. A token with no value is replaced with an empty string, never left showing on the page.
A4: Used by | B4: Token | C4: Source table | D4: Field / meaning
A5: Job | B5: {{Job.JobID}} | C5: tblJobs | D5: JobID
A6: Job | B6: {{Job.CreatedOn}} | C6: tblJobs | D6: CreatedOn
A7: Job | B7: {{Job.CustomerID}} | C7: tblJobs | D7: CustomerID
A8: Job | B8: {{Job.SiteID}} | C8: tblJobs | D8: SiteID
A9: Job | B9: {{Job.ServiceType}} | C9: tblJobs | D9: ServiceType
A10: Job | B10: {{Job.ContainerType}} | C10: tblJobs | D10: ContainerType
A11: Job | B11: {{Job.AssetID}} | C11: tblJobs | D11: AssetID
A12: Job | B12: {{Job.RequestedDate}} | C12: tblJobs | D12: RequestedDate
A13: Job | B13: {{Job.ScheduledDate}} | C13: tblJobs | D13: ScheduledDate
A14: Job | B14: {{Job.CompletedDate}} | C14: tblJobs | D14: CompletedDate
A15: Job | B15: {{Job.Status}} | C15: tblJobs | D15: Status
... A157: Any | B157: {{Date}} | C157: - | D157: Free text date asked for at generation time (manual templates).

Sheet Data_Customers
A1: CustomerID | B1: CustomerName | C1: CustomerType | D1: ContactName | E1: Email | F1: Phone | G1: Address1 | H1: Address2 | I1: Town | J1: Postcode | K1: VATNumber | L1: PaymentTerms | M1: CreditLimit | N1: OnStop | O1: Status | P1: Notes | Q1: CreatedOn | R1: CreatedBy

Sheet Data_Sites
A1: SiteID | B1: CustomerID | C1: SiteName | D1: Address1 | E1: Town | F1: Postcode | G1: What3Words | H1: AccessNotes | I1: PermitRequired | J1: PermitAuthority | K1: SiteContact | L1: SiteContactPhone | M1: Status

Sheet Data_Assets
A1: AssetID | B1: AssetRef | C1: ContainerType | D1: SizeYd3 | E1: AcquiredOn | F1: Status | G1: CurrentSiteID | H1: CurrentJobID | I1: OnHireSince | J1: LastInspection | K1: InspectionMonths | L1: NextInspection | M1: Notes | N1: DaysOnHire

Sheet Data_Vehicles
A1: VehicleID | B1: Registration | C1: VehicleType | D1: MakeModel | E1: GrossWeightKg | F1: UnladenWeightKg | G1: TaxDue | H1: MOTDue | I1: InsuranceDue | J1: LOLERDue | K1: TachoCalDue | L1: ServiceDue | M1: OLicenceRef | N1: Status

Sheet Data_Drivers
A1: DriverID | B1: StaffID | C1: FullName | D1: Mobile | E1: LicenceNumber | F1: LicenceExpiry | G1: CPCExpiry | H1: ADRExpiry | I1: MedicalDue | J1: StartDate | K1: Status

Sheet Data_Staff
A1: StaffID | B1: FullName | C1: Role | D1: Department | E1: Email | F1: StartDate | G1: Status

Sheet Data_WasteStreams
A1: EWCCode | B1: Description | C1: StreamGroup | D1: Hazardous | E1: RecoveryRoute | F1: DefaultOutletID | G1: LandfillTaxBand | H1: Notes

Sheet Data_Outlets
A1: OutletID | B1: OutletName | C1: OutletType | D1: PermitNumber | E1: PermitExpiry | F1: PermitVerifiedOn | G1: Address | H1: Postcode | I1: AcceptedEWC | J1: GateFeePerTonne | K1: Contact | L1: Status

Sheet Data_PriceList
A1: PriceID | B1: EffectiveFrom | C1: EffectiveTo | D1: CustomerID | E1: ServiceType | F1: ContainerType | G1: WasteGroup | H1: HireDaysIncluded | I1: Price | J1: ExcessPerDay | K1: TonnageIncluded | L1: ExcessPerTonne | M1: Notes

Sheet Data_Suppliers
A1: SupplierID | B1: SupplierName | C1: Category | D1: Contact | E1: Email | F1: Phone | G1: ApprovalStatus | H1: CarrierLicence | I1: CarrierLicExpiry | J1: InsuranceExpiry | K1: LastReviewDate | L1: ReviewMonths | M1: NextReviewDue | N1: Notes

Sheet Data_Jobs
A1: JobID | B1: CreatedOn | C1: CustomerID | D1: SiteID | E1: ServiceType | F1: ContainerType | G1: AssetID | H1: RequestedDate | I1: ScheduledDate | J1: CompletedDate | K1: Status | L1: DriverID | M1: VehicleReg | N1: PermitRef | O1: PONumber | P1: PriceAgreed | Q1: EWCCode | R1: WasteDescription | S1: DaysOnHire | T1: SourceRef | U1: Notes | V1: MonthStart | W1: IsOpen | X1: CustomerName | Y1: SitePostcode

Sheet Data_Movements
A1: MovementID | B1: JobID | C1: MovementType | D1: MovementDateTime | E1: AssetID | F1: FromLocation | G1: ToLocation | H1: DriverID | I1: VehicleReg | J1: Notes

Sheet Data_WeighTickets
A1: TicketNo | B1: TicketDateTime | C1: Direction | D1: VehicleReg | E1: JobID | F1: CustomerID | G1: OutletID | H1: EWCCode | I1: GrossKg | J1: TareKg | K1: NetKg | L1: NetTonnes | M1: Weighbridge | N1: Operator | O1: Source | P1: ImportBatch | Q1: Matched | R1: Notes | S1: StreamGroup | T1: RecoveryRoute | U1: Hazardous | V1: MonthStart | W1: NetT | X1: CustomerName

Sheet Data_TransferNotes
A1: WTNRef | B1: DocType | C1: IssueDate | D1: JobID | E1: CustomerID | F1: SiteID | G1: EWCCode | H1: WasteDescription | I1: SICCode | J1: ContainerType | K1: QuantityTonnes | L1: CarrierLicence | M1: ProducerSignedBy | N1: ProducerSignedOn | O1: CarrierSignedBy | P1: DocumentPath | Q1: RetentionUntil | R1: Status | S1: MonthStart

Sheet Data_InvoiceLines
A1: LineID | B1: InvoiceNo | C1: InvoiceDate | D1: CustomerID | E1: JobID | F1: Description | G1: Qty | H1: UOM | I1: UnitPrice | J1: NetAmount | K1: VATRate | L1: VATAmount | M1: GrossAmount | N1: Status | O1: ExportedOn | P1: MonthStart

Sheet Data_EmailLog
A1: EmailID | B1: ReceivedOn | C1: SenderName | D1: SenderEmail | E1: Subject | F1: Category | G1: MatchedCustomerID | H1: MatchedJobID | I1: ExtractedPostcode | J1: ExtractedPhone | K1: ExtractedContainer | L1: ExtractedDate | M1: AttachmentCount | N1: AttachmentFolder | O1: OutlookEntryID | P1: Processed | Q1: ProcessedOn | R1: ActionTaken | S1: BodyExtract

Sheet Data_DocsIssued
A1: IssueID | B1: GeneratedOn | C1: TemplateName | D1: DocType | E1: JobID | F1: CustomerID | G1: FilePath | H1: GeneratedBy

Sheet Data_DocRegister
A1: DocID | B1: DocTitle | C1: DocType | D1: Standard | E1: ISOClause | F1: Owner | G1: Revision | H1: IssueDate | I1: ReviewMonths | J1: ReviewDue | K1: Status | L1: Location | M1: SupersededBy | N1: Notes

Sheet Data_NCR
A1: NCRID | B1: RaisedOn | C1: RaisedBy | D1: Source | E1: Type | F1: Severity | G1: Description | H1: LinkedJobID | I1: LinkedCustomerID | J1: ImmediateCorrection | K1: RootCause | L1: CorrectiveAction | M1: ActionOwner | N1: DueDate | O1: ClosedOn | P1: EffectivenessCheck | Q1: Status | R1: DaysOpen | S1: Overdue

Sheet Data_Audits
A1: AuditID | B1: AuditType | C1: Standard | D1: Scope | E1: PlannedDate | F1: ActualDate | G1: Auditor | H1: Auditee | I1: FindingsMajor | J1: FindingsMinor | K1: Observations | L1: ReportPath | M1: Status

Sheet Data_Training
A1: TrainingID | B1: StaffID | C1: StaffName | D1: Course | E1: Provider | F1: CompletedOn | G1: ValidMonths | H1: ExpiresOn | I1: CertificatePath | J1: Cost | K1: Role

Sheet Data_RequiredTraining
A1: ReqID | B1: Role | C1: Course | D1: Mandatory | E1: RefreshMonths | F1: Notes

Sheet Data_Calibration
A1: EquipmentID | B1: Description | C1: Location | D1: SerialNo | E1: Provider | F1: LastCalibration | G1: FrequencyMonths | H1: NextDue | I1: CertificatePath | J1: Status

Sheet Data_Permits
A1: PermitID | B1: PermitType | C1: Reference | D1: Holder | E1: IssuingBody | F1: IssueDate | G1: ExpiryDate | H1: RenewalLeadDays | I1: AnnualCost | J1: DocumentPath | K1: Status | L1: Notes

Sheet Data_Incidents
A1: IncidentID | B1: IncidentDateTime | C1: Type | D1: Location | E1: PersonInvolved | F1: Description | G1: RIDDORReportable | H1: RIDDORRef | I1: ReportedOn | J1: LostTimeDays | K1: ImmediateAction | L1: RootCause | M1: ActionsTaken | N1: LinkedNCRID | O1: ClosedOn | P1: Status

Sheet Data_LegalRegister
A1: RegID | B1: Legislation | C1: Applicability | D1: Requirement | E1: HowWeComply | F1: Evidence | G1: Owner | H1: LastReviewed | I1: ReviewMonths | J1: NextReview | K1: ComplianceStatus

Sheet Data_Objectives
A1: ObjID | B1: Standard | C1: Objective | D1: KPI | E1: Baseline | F1: Target | G1: CurrentValue | H1: Progress | I1: TargetDate | J1: Owner | K1: Status | L1: ReviewNotes

Sheet Data_RisksOpps
A1: RiskID | B1: Type | C1: Category | D1: Description | E1: Likelihood | F1: Impact | G1: GrossScore | H1: Controls | I1: ResLikelihood | J1: ResImpact | K1: NetScore | L1: Owner | M1: ReviewDate | N1: Status

Sheet Data_MgmtReview
A1: MRID | B1: ReviewDate | C1: Chair | D1: Attendees | E1: InputsCovered | F1: Decisions | G1: ActionsRaised | H1: MinutesPath | I1: NextReviewDue

Sheet Data_SupplierEval
A1: EvalID | B1: SupplierID | C1: SupplierName | D1: EvalDate | E1: ScoreQuality | F1: ScoreDelivery | G1: ScoreCompliance | H1: ScorePrice | I1: ScoreHSE | J1: TotalScore | K1: Outcome | L1: Reviewer | M1: Comments | N1: NextEvalDue

Sheet _Lists
A4: ApprovalStatus | B4: AssetStatus | C4: AuditType | D4: Compliance | E4: ContainerType | F4: CustomerType | G4: Direction | H4: DocStatus | I4: DocType | J4: EmailCategory | K4: IncidentType | L4: InvoiceStatus | M4: JobStatus | N4: LikertScore | O4: MovementType | P4: NCRSource | Q4: NCRType | R4: OpenClosed | S4: OutletType | T4: PaymentTerms | U4: PermitType | V4: RecordStatus | W4: RecoveryRoute | X4: RiskType | Y4: ServiceType | Z4: Severity | AA4: Standard | AB4: StreamGroup | AC4: UOM | AD4: WTNDocType | AE4: YesNo
A5: Approved | B5: Available | C5: Internal | D5: Compliant | E5: 2yd Skip | F5: Trade | G5: In | H5: Draft | I5: Policy | J5: Booking | K5: Injury | L5: Draft | M5: Enquiry | N5: 1 | O5: Delivered | P5: Internal Audit | Q5: Quality | R5: Open | S5: Materials Recovery Facility | T5: Pro Forma | U5: Environmental Permit | V5: Active | W5: Recycling | X5: Risk | Y5: Delivery | Z5: Major | AA5: ISO 9001 | AB5: Mixed C&D | AC5: Job | AD5: Waste Transfer Note | AE5: Yes
A6: Provisional | B6: On Hire | C6: Certification | D6: Partially Compliant | E6: 4yd Skip | F6: Domestic | G6: Out | H6: In Review | I6: Manual | J6: Enquiry | K6: Near Miss | L6: Approved | M6: Quoted | N6: 2 | O6: Exchanged Out | P6: External Audit | Q6: Environmental | R6: In Progress | S6: Transfer Station | T6: Card on Booking | U6: Waste Carrier Licence | V6: Inactive | W6: Reuse | X6: Opportunity | Y6: Exchange | Z6: Minor | AA6: ISO 14001 | AB6: Inert | AC6: Tonne | AD6: Season Ticket (Annual WTN) | AE6: No
A7: Under Review | B7: In Transit | C7: Surveillance | D7: Non-Compliant | E7: 6yd Skip | F7: Local Authority | H7: Issued | I7: Procedure | J7: Quote Request | K7: Environmental | L7: Exported | M7: Booked | N7: 3 | O7: Exchanged In | P7: Customer Complaint | Q7: Health & Safety | R7: Awaiting Verification | S7: Reprocessor | T7: 7 Days | U7: Waste Broker Registration | V7: Archived | W7: Recovery (Energy) | Y7: Collection | Z7: Observation | AA7: ISO 45001 | AB7: Soil | AC7: Day | AD7: Hazardous Consignment Note
A8: Suspended | B8: Maintenance | C8: Regulator | D8: Not Applicable | E8: 8yd Skip | F8: Main Contractor | H8: Superseded | I8: Work Instruction | J8: Weighbridge Ticket | K8: Spill | L8: Invoiced | M8: Allocated | N8: 4 | O8: Collected | P8: Driver Report | Q8: Compliance | R8: Closed | S8: EfW | T8: 14 Days | U8: Operator Licence | W8: Treatment | Y8: Wait and Load | AA8: Multiple | AB8: Wood | AC8: Load
A9: Rejected | B9: Repair | C9: Customer | D9: Under Assessment | E9: 12yd Skip | F9: Broker | H9: Withdrawn | I9: Form | J9: Invoice Query | K9: Fire | L9: Paid | M9: On Site | N9: 5 | O9: Returned to Yard | P9: Weighbridge | Q9: Commercial | R9: Cancelled | S9: Landfill | T9: 30 Days | U9: Planning Consent | W9: Landfill | Y9: Tip and Return | AA9: Statutory | AB9: Metal | AC9: Item
B10: Lost | C10: Supplier | E10: 14yd Skip | F10: Internal | I10: Register | J10: Complaint | K10: Road Traffic Collision | L10: Credited | M10: Awaiting Collection | O10: Transferred | P10: Site Inspection | S10: Inert Recovery | T10: 30 Days EOM | U10: Trade Effluent Consent | Y10: Muckaway | AA10: Internal | AB10: Plasterboard | AC10: Hour
B11: Scrapped | E11: 20yd RoRo | I11: Record | J11: Supplier | K11: Property Damage | L11: Disputed | M11: Completed | O11: Off Hire | P11: Supplier | S11: Composting | T11: 60 Days | U11: Duty of Care Exemption | Y11: Aborted Visit | AB11: Green Waste | AC11: Mile
E12: 35yd RoRo | I12: Plan | J12: Compliance | K12: Dangerous Occurrence | M12: Invoiced | P12: Incident | S12: Metal Merchant | U12: Insurance | AB12: Mixed General
E13: 40yd RoRo | I13: External Document | J13: Internal | K13: Ill Health | M13: Cancelled | P13: Management Review | S13: Hazardous Facility | AB13: Cardboard
E14: Front End Loader | J14: Spam | M14: Aborted | AB14: Plastics
E15: Wheelie Bin 1100L | J15: Unclassified | AB15: WEEE
AB16: Hazardous
AB17: Fines/Residue
